Workbook

Sheet input
B1: esempio
A2: cella contenente valore numerico | B2: 314
A3: cella contenente valore numerico con virgola | B3: 0.13472222
A4: cella contenente valore testuale | B4: tre
A5: cella contenente una data come valore | B5: 46126
A7: riferimenti
A8: cella contenente un valore testuale (non un riferimento, manca =) | B8: B2
A9: cella contenente un riferimento alla cella B2 | B9: =B2 -> 314
A10: cella contenente un riferimento alla cella B2 con indice di colonna bloccato ($) | B10: =$B2 -> 314
A11: cella contenente un riferimento alla cella B2 con indice di riga bloccato ($) | B11: =B$2 -> 314
A12: cella contenente un riferimento alla cella B2 con indici bloccati ($) | B12: =$B$2 -> 314
A13: cella contenente un riferimento alla cella di un altro foglio
A15: formula
A16: formula con costanti numeriche | B16: =1+2*3/4 -> 2.5
A17: formula con riferimenti | B17: =1+B9*B2/4 -> 24650
A18: formula con funzione SOMMA(1) argomento un valore numerico | B18: =SUM(1) -> 1
A19: formula con funzione SOMMA(B2) argomento un riferimento | B19: =SUM(B2) -> 314
A20: formula con funzione SOMMA(B2:B4) argomento un intervallo | B20: =SUM(B2:B4) -> 314.13472
A22: funzioni | B22: dati
B23: 1
B24: 2
B25: 3
B26: 4
B27: 5
A29: funzione SOMMA | B29: =SUM(B23:B27) -> 15
A30: funzione MEDIA | B30: =AVERAGE(B23:B27) -> 3
A31: funzione MIN | B31: =MIN(B23:B27) -> 1
A32: funzione MAX | B32: =MAX(B23:B27) -> 5

Sheet trascinamento
D1: -3 | V1: =T6
D2: -2
D3: -1
A4: -3 | B4: -2 | C4: -1 | D4: 0 | E4: 1 | F4: 2 | G4: 3
D5: 1
D6: 2
D7: 3
A9: trascinamento
A10: con valore costante 0 | I10: con riferimento =D4
D12: 0 | L12: =D1 -> -3
D13: 0 | L13: =D2 -> -2
D14: 0 | L14: =D3 -> -1
A15: 0 | B15: 0 | C15: 0 | D15: a | E15: 0 | F15: 0 | G15: 0 | I15: =A4 -> -3 | J15: =B4 -> -2 | K15: =C4 -> -1 | L15: =D4 -> 0 | M15: =E4 -> 1 | N15: =F4 -> 2 | O15: =G4 -> 3
D16: a | L16: =D5 -> 1
D17: a | L17: =D6 -> 2
D18: a | L18: =D7 -> 3
A20: con riferimento bloccato =$D4 | I20: con riferimento bloccato =D$4
D22: =$D1 -> -3 | L22: =D$4 -> 0
D23: =$D2 -> -2 | L23: =D$4 -> 0
D24: =$D3 -> -1 | L24: =D$4 -> 0
A25: =$D4 -> 0 | B25: =$D4 -> 0 | C25: =$D4 -> 0 | D25: =$D4 -> 0 | E25: =$D4 -> 0 | F25: =$D4 -> 0 | G25: =$D4 -> 0 | I25: =A$4 -> -3 | J25: =B$4 -> -2 | K25: =C$4 -> -1 | L25: =D$4 -> 0 | M25: =E$4 -> 1 | N25: =F$4 -> 2 | O25: =G$4 -> 3
D26: =$D5 -> 1 | L26: =D$4 -> 0
D27: =$D6 -> 2 | L27: =D$4 -> 0
D28: =$D7 -> 3 | L28: =D$4 -> 0
A30: con riferimento bloccato =$D$4
D32: =$D$4 -> 0
D33: =$D$4 -> 0
D34: =$D$4 -> 0
A35: =$D$4 -> 0 | B35: =$D$4 -> 0 | C35: =$D$4 -> 0 | D35: =$D$4 -> 0 | E35: =$D$4 -> 0 | F35: =$D$4 -> 0 | G35: =$D$4 -> 0
D36: =$D$4 -> 0
D37: =$D$4 -> 0
D38: =$D$4 -> 0

Sheet formattazione_condizionale
A1: formattazione condizionale
A28: se la cella contiene:
A29: - un valore minore o uguale di 4 imposta lo sfondo rosso | B29: 4
A30: - un valore da 5 a 6 imposta lo sfondo arancione | B30: 5
A31: - un valore maggiore di 6 imposta lo sfondo verde | B31: 8
A33: se la cella contiene:
A34: - una data successiva a oggi imposta sfondo rosso | B34: 46023
A35: - una data precedente o uguale a oggi imposta sfondo verde e grassetto | B35: 49675
A37: se le celle contengono: | B37: dati
A38: - il testo "lu" sfondo verde | B38: anna
A39: - casella vuota sfondo rosso | B39: luca
B41: mario
B42: lucia

Sheet grafici
A1: grafici | B1: X | C1: Y
B2: 1 | C2: =B2*B2 -> 1
B3: 2 | C3: =B3*B3 -> 4
B4: 3 | C4: =B4*B4 -> 9
B5: 4 | C5: =B5*B5 -> 16
B6: 5 | C6: =B6*B6 -> 25
B7: 6 | C7: =B7*B7 -> 36
B8: 7 | C8: =B8*B8 -> 49
B9: 8 | C9: =B9*B9 -> 64
B10: 9 | C10: =B10*B10 -> 81
B11: 10 | C11: =B11*B11 -> 100

Sheet percentuali
A1: percentuali | B1: valori
A2: costo base (merce fornitore) | B2: 40 | C2: €
A3: prezzo di vendita (ricarico del 300%) | B3: =B2*300% -> 120 | C3: €
A4: sconto del 35% | B4: =B3*35% -> 42 | C4: €
A5: prezzo scontato del 35% | B5: =B3 - B4 -> 78 | C5: €
A6: rateizzazione (3 rate) | B6: =B5/3 -> 26 | C6: €
A7: ricavo con tasso interesse sulle rate 5% | B7: =B6*(1+5%)*3 -> 81.9 | C7: €

Sheet funzioni_avanzate
A1: Funzioni avanzate
A2: dati di esempio | B2: case | C2: nome | D2: eta
B3: 1 | C3: luca | D3: 30 | E3: sesso
C4: marco | D4: 14 | E4: M
B5: 2 | C5: giovanni | D5: 50 | E5: M
C6: anna | D6: 25 | E6: M
B7: 3 | C7: paola | D7: 55 | E7: F
B8: 4 | C8: federica | D8: 60 | E8: F
E9: F
A10: conta le celle vuote sulla colonna B (funzione CONTA.VUOTE) | B10: =COUNTBLANK(B3:B8) -> 2
A11: conta le celle con valore sulla colonna B (funzione CONTA.VALORI) | B11: =COUNTA(B3:B8) -> 4
A12: conta le celle con valore maggiore di 1 sulla colonna B (funzione CONTA.SE) | B12: =COUNTIF(B3:B8,">1") -> 3
A13: somma i valori della colonna B se maggiori di 1 (funzione SOMMA.SE) | B13: =SUMIF(B4:B9,">1") -> 9
A14: fai la media dei valori della colonna B se maggiori di 2 (funzione MEDIA.SE) | B14: =AVERAGEIF(B5:B10,">2") -> 3.5
A15: cerca l'eta' di "anna" (con funzione CERCA.VERT) | B15: =VLOOKUP("anna", C3:D8, 2, FALSE) -> 25
A16: cerca il sesso di "giovanni" sapendo che le colonne nome e sesso sono sfalsate (funzione CERCA.X) | B16: {=XLOOKUP("giovanni",C3:C8,E4:E9)} -> M

Sheet ripasso
A1: tipi di dato | B1: cerca di fare tutti gli esercizi usando il meno possibile il mouse (non serve quasi mai) e il piu' possibile la tastiera
A2: inserisci nella cella un valore numerico
A3: inserisci nella cella un valore numerico con virgola
A4: inserisci nella cella un valore testuale
A5: inserisci nella cella la data di oggi
A7: riferimenti
A8: e' un riferimento? perche? | B8: B2
A9: inserisci un riferimento alla cella B2 | B9: $A$1
A10: inserisci un riferimento alla cella B2 con indice di riga bloccato | B10: $A1
A11: inserisci un riferimento alla cella B2 con indice di colonna bloccato | B11: tabella_articolo!A1
A12: inserisci un riferimento alla cella B2 con indici bloccati
A13: inserisci un riferimento alla cella B2 del foglio input
A15: trascinamento
A16: usando il trascinamento in orizzontale genera i numeri da -10 a +10 su questa riga
A17: usando il trascinamento in orizzontale genera le date dal primo giorno del mese all'ultimo
A18: usando il trascinamento calcola la somma della cella in cui sei con la corrispondente (stessa colonna) di riga 16
A20: funzioni
A21: dati i seguenti dati: | B21: dati
B22: 1
B23: 2
B24: 4
B25: 8
B26: 16
A28: calcolare la media
A29: calcolare la somma
A30: calcolare il minimo
A31: calcolare il massimo
A33: formattazione condizionale
A34: formatta la cella in grassetto se il numero e' maggiore di 100
A35: formatta la cella con testo rosso se il numero e' fra 0 e 50
A36: formatta la cella con sfondo verde se la data e' successiva ad oggi
A37: formatta la cella con sfondo rosso se la cella e' vuota
A39: grafici | B39: x | C39: y
A40: disegna il grafico della funzione y = 3x + 10 usando una funzione con riferimenti e trascinamento
A51: disegna un grafico a barre (istogramma) con i dati | B51: nome | C51: capitale
B52: anna | C52: 100000 | D52: $
B53: marco | C53: 20000 | D53: $
B54: luca | C54: 150000 | D54: $
B55: lucia | C55: 85000 | D55: $
A57: funzioni avanzate
...

Sheet filtri
A1: filtri | C1: id | D1: codice | E1: nome | F1: prezzo | G1: iva | H1: unità
A2: crea un filtro sulla tabella | C2: 1 | D2: A1 | E2: vino | F2: 4.99 | G2: 22 | H2: litri
A3: filtra per id 1 e 3 | C3: 2 | D3: A2 | E3: vino | F3: 4 | G3: 22 | H3: litri
A4: filtra per codice A1 | C4: 3 | D4: A3 | E4: latte | F4: 1.5 | G4: 4 | H4: litri
A5: filtra per nome contenente "i" | C5: 4 | D5: A4 | E5: biscotti | F5: 2.5 | G5: 10 | H5: grammi
A6: filtra per iva > 4%
A7: filtra per unita' litri

Sheet convalida_dati
A1: convalida dei dati | B1: cella
B3: 101
A16: mostra avviso se la cella non contiene un numero maggiore di 100 | B16: 105
A17: rifiuta input se la cella non contiene un numero fra 1 e 10 | B17: 5
A18: mostra avviso se la data successiva ad oggi | B18: 49794
A19: rifiuta input se viene inserito un indirizzo email invalido | B19: mario.rossi@gmail.com
A21: Menu a tendina
A23: con tre opzioni fisse (Lavoratore, Studente e Disoccupato) | B23: Lavoratore
A24: con gli articoli della tabella_articolo | B24: biscotti
A26: Casella di controllo
B27: FALSE
B28: FALSE | C28: FALSE
B29: FALSE | C29: TRUE
B30: FALSE | C30: FALSE
B31: FALSE | C31: TRUE
B32: FALSE | C32: FALSE

Sheet cerca
A1: Ricerca articolo per codice: | B1: A4
A3: nome | B3: prezzo | C3: iva | D3: unità | E3: codice
A4: {=XLOOKUP($B$1,tabella_articolo!$B$2:$B$5,tabella_articolo!C2:C5)} -> biscotti | B4: {=XLOOKUP($B$1,tabella_articolo!$B$2:$B$5,tabella_articolo!D2:D5)} -> 2.5 | C4: {=XLOOKUP($B$1,tabella_articolo!$B$2:$B$5,tabella_articolo!E2:E5)} -> 10 | D4: {=XLOOKUP($B$1,tabella_articolo!$B$2:$B$5,tabella_articolo!F2:F5)} -> grammi | E4: {=XLOOKUP($B$1,tabella_articolo!$B$2:$B$5,tabella_articolo!B2:B5)} -> A4
A7: Ricerca fornitore per codice:
A9: nome | B9: telefono | C9: email | D9: indrizzo | E9: partita_iva | F9: codice fornitore | G9: via | H9: nome_via | I9: numero_civico
A13: Ricerca inventario per codice:
A15: nome | B15: telefono | C15: email | D15: indrizzo | E15: partita_iva | F15: codice fornitore | G15: via | H15: nome_via | I15: numero_civico

Sheet tabella_articolo
A1: id | B1: codice | C1: nome | D1: prezzo | E1: iva | F1: unità
A2: 1 | B2: A1 | C2: vino | D2: 4.99 | E2: 22 | F2: litri
A3: 2 | B3: A2 | C3: vino | D3: 4 | E3: 22 | F3: litri
A4: 3 | B4: A3 | C4: latte | D4: 1.5 | E4: 4 | F4: litri
A5: 4 | B5: A4 | C5: biscotti | D5: 2.5 | E5: 10 | F5: grammi

Sheet tabella_fornitore
A1: id | B1: codice | C1: nome | D1: telefono | E1: email | F1: indrizzo | G1: partita_iva | H1: via | I1: nome_via | J1: numero_civico
A2: 1 | B2: F2 | C2: mila | D2: 3481234567 | E2: cantina@rovere.della.luna.it | F2: via ottobre 34 | G2: 123456789 | H2: via | I2: ottobre | J2: 34

Sheet tabella_inventario
A1: id | B1: codice_articolo | C1: codice_fornitore | D1: posizione | E1: nome_articolo | F1: quantità
A2: 1 | B2: A4 | C2: F3 | D2: scaffale 1 | E2: biscotti | F2: 23
A3: 2 | B3: A1 | C3: F1 | D3: scaffale 2 | E3: vino | F3: 12
A4: 3 | B4: A3 | C4: F2 | D4: scaffale 3 | E4: latte | F4: 54
A5: 4 | B5: A2 | C5: F1 | D5: scaffale 4 | E5: vino | F5: 40

Sheet fattura
D1: Crea una convalida con menù a discesa sotto "Descrizione" con i nomi presi dal foglio Prodotti
C3: Quantità | D3: Descrizione | I3: IVA | J3: Prezzi unitari | K3: Importo
A4: Crea una convalida che accetti solo numeri positivi sotto "Quantità" | L4: ← Usa la funzione cerca.vert() per estrarre dal database le informazioni (IVA, Prezzo unitario)
C12: Totale Imponibile: | L12: ← Qui metti la somma degli importi
C14: Imponibile IVA 4% | F14: Imponibile IVA 10% | I14: Imponibile IVA 22%
L16: ← Usa la funzione somma.se() per calcolare gli imponibili di ciasciuna sezione delle tasse
C18: IVA 4% | F18: IVA 10% | I18: IVA 22%
L20: ← Calcola le tasse per ciasciun imponibile
C22: Totale IVA | F22: Totale Fattura
L24: ← Somma le tasse e calcola il totale della fattura!
